[2020-06-13 12:11:39,366] {taskinstance.py:669} INFO - Dependencies all met for <TaskInstance: simple_dag.greet 2020-06-01T10:00:00+00:00 [queued]>
[2020-06-13 12:11:39,375] {taskinstance.py:669} INFO - Dependencies all met for <TaskInstance: simple_dag.greet 2020-06-01T10:00:00+00:00 [queued]>
[2020-06-13 12:11:39,376] {taskinstance.py:879} INFO - 
--------------------------------------------------------------------------------
[2020-06-13 12:11:39,376] {taskinstance.py:880} INFO - Starting attempt 2 of 2
[2020-06-13 12:11:39,376] {taskinstance.py:881} INFO - 
--------------------------------------------------------------------------------
[2020-06-13 12:11:39,389] {taskinstance.py:900} INFO - Executing <Task(PythonOperator): greet> on 2020-06-01T10:00:00+00:00
[2020-06-13 12:11:39,391] {standard_task_runner.py:53} INFO - Started process 78902 to run task
[2020-06-13 12:11:39,435] {logging_mixin.py:112} INFO - Running %s on host %s <TaskInstance: simple_dag.greet 2020-06-01T10:00:00+00:00 [running]> nineleaps-ThinkPad-E480
[2020-06-13 12:11:39,447] {logging_mixin.py:112} INFO - Writing in file
[2020-06-13 12:11:39,447] {taskinstance.py:1145} ERROR - join() got an unexpected keyword argument 'path'
Traceback (most recent call last):
  File "/home/nineleaps/PycharmProjects/airflow_2/venv/lib/python3.6/site-packages/airflow/models/taskinstance.py", line 983, in _run_raw_task
    result = task_copy.execute(context=context)
  File "/home/nineleaps/PycharmProjects/airflow_2/venv/lib/python3.6/site-packages/airflow/operators/python_operator.py", line 113, in execute
    return_value = self.execute_callable()
  File "/home/nineleaps/PycharmProjects/airflow_2/venv/lib/python3.6/site-packages/airflow/operators/python_operator.py", line 118, in execute_callable
    return self.python_callable(*self.op_args, **self.op_kwargs)
  File "/home/nineleaps/PycharmProjects/airflow_2/airflow/dags/simple_dag.py", line 13, in greet
    output_path = os.path.join(dirpath, path=PATH)
TypeError: join() got an unexpected keyword argument 'path'
[2020-06-13 12:11:39,448] {taskinstance.py:1187} INFO - All retries failed; marking task as FAILED.dag_id=simple_dag, task_id=greet, execution_date=20200601T100000, start_date=20200613T064139, end_date=20200613T064139
[2020-06-13 12:11:49,357] {logging_mixin.py:112} INFO - [2020-06-13 12:11:49,356] {local_task_job.py:103} INFO - Task exited with return code 1
[2020-06-13 12:25:08,004] {taskinstance.py:669} INFO - Dependencies all met for <TaskInstance: simple_dag.greet 2020-06-01T10:00:00+00:00 [queued]>
[2020-06-13 12:25:08,022] {taskinstance.py:669} INFO - Dependencies all met for <TaskInstance: simple_dag.greet 2020-06-01T10:00:00+00:00 [queued]>
[2020-06-13 12:25:08,023] {taskinstance.py:879} INFO - 
--------------------------------------------------------------------------------
[2020-06-13 12:25:08,023] {taskinstance.py:880} INFO - Starting attempt 2 of 2
[2020-06-13 12:25:08,023] {taskinstance.py:881} INFO - 
--------------------------------------------------------------------------------
[2020-06-13 12:25:08,039] {taskinstance.py:900} INFO - Executing <Task(PythonOperator): greet> on 2020-06-01T10:00:00+00:00
[2020-06-13 12:25:08,044] {standard_task_runner.py:53} INFO - Started process 82005 to run task
[2020-06-13 12:25:08,130] {logging_mixin.py:112} INFO - Running %s on host %s <TaskInstance: simple_dag.greet 2020-06-01T10:00:00+00:00 [running]> nineleaps-ThinkPad-E480
[2020-06-13 12:25:08,149] {logging_mixin.py:112} INFO - Writing in file
[2020-06-13 12:25:08,150] {taskinstance.py:1145} ERROR - [Errno 2] No such file or directory: '/output/greet.txt'
Traceback (most recent call last):
  File "/home/nineleaps/PycharmProjects/airflow_2/venv/lib/python3.6/site-packages/airflow/models/taskinstance.py", line 983, in _run_raw_task
    result = task_copy.execute(context=context)
  File "/home/nineleaps/PycharmProjects/airflow_2/venv/lib/python3.6/site-packages/airflow/operators/python_operator.py", line 113, in execute
    return_value = self.execute_callable()
  File "/home/nineleaps/PycharmProjects/airflow_2/venv/lib/python3.6/site-packages/airflow/operators/python_operator.py", line 118, in execute_callable
    return self.python_callable(*self.op_args, **self.op_kwargs)
  File "/home/nineleaps/PycharmProjects/airflow_2/airflow/dags/simple_dag.py", line 14, in greet
    with open(output_path, 'a+', encoding='utf8') as f:
FileNotFoundError: [Errno 2] No such file or directory: '/output/greet.txt'
[2020-06-13 12:25:08,151] {taskinstance.py:1187} INFO - All retries failed; marking task as FAILED.dag_id=simple_dag, task_id=greet, execution_date=20200601T100000, start_date=20200613T065508, end_date=20200613T065508
[2020-06-13 12:25:17,980] {logging_mixin.py:112} INFO - [2020-06-13 12:25:17,980] {local_task_job.py:103} INFO - Task exited with return code 1
